<robot name = "robot">
    <link name="Link0">
        <inertial>
            <origin xyz="0 0 0.3871723378340507" rpy="0 0 0"/>
            <mass value="1" />
            <inertia ixx="100" ixy="0" ixz="0" iyy="100" iyz="0" izz="100" />
        </inertial>
        <visual>
            <origin xyz="0 0 0.3871723378340507" rpy="0 0 0"/>
            <geometry>
                <box size="0.7654605656128823 0.9496198950807603 0.7743446756681014" />
            </geometry>
            <material name="Blue">
                <color rgba="0 0 1 1"/>
            </material>
        </visual>
        <collision>
            <origin xyz="0 0 0.3871723378340507" rpy="0 0 0"/>
            <geometry>
                <box size="0.7654605656128823 0.9496198950807603 0.7743446756681014" />
            </geometry>
        </collision>
    </link>
    <joint name="Link0_Link1" type="revolute">
       <parent link="Link0"/>
       <child  link="Link1"/>
       <origin rpy="0 0 0" xyz="0 0.47480994754038014 0.3871723378340507" />
     <axis xyz="1 0 0"/>
       <limit effort="0.0" lower="-3.14159" upper="3.14159" velocity="0.0"/>
    </joint>
    <link name="Link1">
        <inertial>
            <origin xyz="0 0.48295380958801626 0" rpy="0 0 0"/>
            <mass value="1" />
            <inertia ixx="100" ixy="0" ixz="0" iyy="100" iyz="0" izz="100" />
        </inertial>
        <visual>
            <origin xyz="0 0.48295380958801626 0" rpy="0 0 0"/>
            <geometry>
                <box size="0.7337609569961252 0.9659076191760325 0.7052346211332136" />
            </geometry>
            <material name="Blue">
                <color rgba="0 0 1 1"/>
            </material>
        </visual>
        <collision>
            <origin xyz="0 0.48295380958801626 0" rpy="0 0 0"/>
            <geometry>
                <box size="0.7337609569961252 0.9659076191760325 0.7052346211332136" />
            </geometry>
        </collision>
    </link>
    <joint name="Link1_Link1XLink0" type="revolute">
       <parent link="Link1"/>
       <child  link="Link1XLink0"/>
       <origin rpy="0 0 0" xyz="0.3668804784980626 0.48295380958801626 0" />
     <axis xyz="1 0 0"/>
       <limit effort="0.0" lower="-3.14159" upper="3.14159" velocity="0.0"/>
    </joint>
    <link name="Link1XLink0">
        <inertial>
            <origin xyz="0.3252011893929726 0 0" rpy="0 0 0"/>
            <mass value="1" />
            <inertia ixx="100" ixy="0" ixz="0" iyy="100" iyz="0" izz="100" />
        </inertial>
        <visual>
            <origin xyz="0.3252011893929726 0 0" rpy="0 0 0"/>
            <geometry>
                <box size="0.6504023787859452 0.7428791149849481 0.758103857921405" />
            </geometry>
            <material name="Blue">
                <color rgba="0 0 1 1"/>
            </material>
        </visual>
        <collision>
            <origin xyz="0.3252011893929726 0 0" rpy="0 0 0"/>
            <geometry>
                <box size="0.6504023787859452 0.7428791149849481 0.758103857921405" />
            </geometry>
        </collision>
    </link>
    <joint name="Link1_Link1MinXLink0" type="revolute">
       <parent link="Link1"/>
       <child  link="Link1MinXLink0"/>
       <origin rpy="0 0 0" xyz="-0.3668804784980626 0.48295380958801626 0" />
     <axis xyz="1 0 0"/>
       <limit effort="0.0" lower="-3.14159" upper="3.14159" velocity="0.0"/>
    </joint>
    <link name="Link1MinXLink0">
        <inertial>
            <origin xyz="-0.3705435434199219 0 0" rpy="0 0 0"/>
            <mass value="1" />
            <inertia ixx="100" ixy="0" ixz="0" iyy="100" iyz="0" izz="100" />
        </inertial>
        <visual>
            <origin xyz="-0.3705435434199219 0 0" rpy="0 0 0"/>
            <geometry>
                <box size="0.7410870868398438 0.8517763274817394 0.9634429481224459" />
            </geometry>
            <material name="Green">
                <color rgba="0 1 0 1"/>
            </material>
        </visual>
        <collision>
            <origin xyz="-0.3705435434199219 0 0" rpy="0 0 0"/>
            <geometry>
                <box size="0.7410870868398438 0.8517763274817394 0.9634429481224459" />
            </geometry>
        </collision>
    </link>
    <joint name="Link1MinXLink0_Link1MinXLink1" type="revolute">
       <parent link="Link1MinXLink0"/>
       <child  link="Link1MinXLink1"/>
       <origin rpy="0 0 0" xyz="-0.7410870868398438 0 0" />
     <axis xyz="1 0 0"/>
       <limit effort="0.0" lower="-3.14159" upper="3.14159" velocity="0.0"/>
    </joint>
    <link name="Link1MinXLink1">
        <inertial>
            <origin xyz="-0.3705435434199219 0 0" rpy="0 0 0"/>
            <mass value="1" />
            <inertia ixx="100" ixy="0" ixz="0" iyy="100" iyz="0" izz="100" />
        </inertial>
        <visual>
            <origin xyz="-0.3705435434199219 0 0" rpy="0 0 0"/>
            <geometry>
                <box size="0.7410870868398438 0.8517763274817394 0.9634429481224459" />
            </geometry>
            <material name="Blue">
                <color rgba="0 0 1 1"/>
            </material>
        </visual>
        <collision>
            <origin xyz="-0.3705435434199219 0 0" rpy="0 0 0"/>
            <geometry>
                <box size="0.7410870868398438 0.8517763274817394 0.9634429481224459" />
            </geometry>
        </collision>
    </link>
    <joint name="Link1_Link1ZLink0" type="revolute">
       <parent link="Link1"/>
       <child  link="Link1ZLink0"/>
       <origin rpy="0 0 0" xyz="0 0.48295380958801626 0.3526173105666068" />
     <axis xyz="0 0 1"/>
       <limit effort="0.0" lower="-3.14159" upper="3.14159" velocity="0.0"/>
    </joint>
    <link name="Link1ZLink0">
        <inertial>
            <origin xyz="0 0 0.4440806914234059" rpy="0 0 0"/>
            <mass value="1" />
            <inertia ixx="100" ixy="0" ixz="0" iyy="100" iyz="0" izz="100" />
        </inertial>
        <visual>
            <origin xyz="0 0 0.4440806914234059" rpy="0 0 0"/>
            <geometry>
                <box size="0.7337609569961252 0.6106336978318692 0.8881613828468118" />
            </geometry>
            <material name="Blue">
                <color rgba="0 0 1 1"/>
            </material>
        </visual>
        <collision>
            <origin xyz="0 0 0.4440806914234059" rpy="0 0 0"/>
            <geometry>
                <box size="0.7337609569961252 0.6106336978318692 0.8881613828468118" />
            </geometry>
        </collision>
    </link>
</robot>