<robot name = "robot">
    <link name="Link0">
        <inertial>
            <origin xyz="0 0 0.35006314778928066" rpy="0 0 0"/>
            <mass value="1" />
            <inertia ixx="100" ixy="0" ixz="0" iyy="100" iyz="0" izz="100" />
        </inertial>
        <visual>
            <origin xyz="0 0 0.35006314778928066" rpy="0 0 0"/>
            <geometry>
                <box size="0.9156703790924303 0.7629597629061032 0.7001262955785613" />
            </geometry>
            <material name="Blue">
                <color rgba="0 0 1 1"/>
            </material>
        </visual>
        <collision>
            <origin xyz="0 0 0.35006314778928066" rpy="0 0 0"/>
            <geometry>
                <box size="0.9156703790924303 0.7629597629061032 0.7001262955785613" />
            </geometry>
        </collision>
    </link>
    <joint name="Link0_Link1" type="revolute">
       <parent link="Link0"/>
       <child  link="Link1"/>
       <origin rpy="0 0 0" xyz="0 0.3814798814530516 0.43420976229280706" />
     <axis xyz="1 0 0"/>
       <limit effort="0.0" lower="-3.14159" upper="3.14159" velocity="0.0"/>
    </joint>
    <link name="Link1">
        <inertial>
            <origin xyz="0 0.37763937999066 0" rpy="0 0 0"/>
            <mass value="1" />
            <inertia ixx="100" ixy="0" ixz="0" iyy="100" iyz="0" izz="100" />
        </inertial>
        <visual>
            <origin xyz="0 0.37763937999066 0" rpy="0 0 0"/>
            <geometry>
                <box size="0.6919802397619708 0.75527875998132 0.8684195245856141" />
            </geometry>
            <material name="Green">
                <color rgba="0 1 0 1"/>
            </material>
        </visual>
        <collision>
            <origin xyz="0 0.37763937999066 0" rpy="0 0 0"/>
            <geometry>
                <box size="0.6919802397619708 0.75527875998132 0.8684195245856141" />
            </geometry>
        </collision>
    </link>
    <joint name="Link1_Link1XLink0" type="revolute">
       <parent link="Link1"/>
       <child  link="Link1XLink0"/>
       <origin rpy="0 0 0" xyz="0.3459901198809854 0.37763937999066 0" />
     <axis xyz="1 0 0"/>
       <limit effort="0.0" lower="-3.14159" upper="3.14159" velocity="0.0"/>
    </joint>
    <link name="Link1XLink0">
        <inertial>
            <origin xyz="0.3897610376959361 0 0" rpy="0 0 0"/>
            <mass value="1" />
            <inertia ixx="100" ixy="0" ixz="0" iyy="100" iyz="0" izz="100" />
        </inertial>
        <visual>
            <origin xyz="0.3897610376959361 0 0" rpy="0 0 0"/>
            <geometry>
                <box size="0.7795220753918722 0.7409783632000847 0.6824786394609406" />
            </geometry>
            <material name="Green">
                <color rgba="0 1 0 1"/>
            </material>
        </visual>
        <collision>
            <origin xyz="0.3897610376959361 0 0" rpy="0 0 0"/>
            <geometry>
                <box size="0.7795220753918722 0.7409783632000847 0.6824786394609406" />
            </geometry>
        </collision>
    </link>
    <joint name="Link1XLink0_Link1XLink1" type="revolute">
       <parent link="Link1XLink0"/>
       <child  link="Link1XLink1"/>
       <origin rpy="0 0 0" xyz="0.7795220753918722 0 0" />
     <axis xyz="1 0 0"/>
       <limit effort="0.0" lower="-3.14159" upper="3.14159" velocity="0.0"/>
    </joint>
    <link name="Link1XLink1">
        <inertial>
            <origin xyz="0.3897610376959361 0 0" rpy="0 0 0"/>
            <mass value="1" />
            <inertia ixx="100" ixy="0" ixz="0" iyy="100" iyz="0" izz="100" />
        </inertial>
        <visual>
            <origin xyz="0.3897610376959361 0 0" rpy="0 0 0"/>
            <geometry>
                <box size="0.7795220753918722 0.7409783632000847 0.6824786394609406" />
            </geometry>
            <material name="Green">
                <color rgba="0 1 0 1"/>
            </material>
        </visual>
        <collision>
            <origin xyz="0.3897610376959361 0 0" rpy="0 0 0"/>
            <geometry>
                <box size="0.7795220753918722 0.7409783632000847 0.6824786394609406" />
            </geometry>
        </collision>
    </link>
    <joint name="Link1_Link1MinXLink0" type="revolute">
       <parent link="Link1"/>
       <child  link="Link1MinXLink0"/>
       <origin rpy="0 0 0" xyz="-0.3459901198809854 0.37763937999066 0" />
     <axis xyz="1 0 0"/>
       <limit effort="0.0" lower="-3.14159" upper="3.14159" velocity="0.0"/>
    </joint>
    <link name="Link1MinXLink0">
        <inertial>
            <origin xyz="-0.4175754253294097 0 0" rpy="0 0 0"/>
            <mass value="1" />
            <inertia ixx="100" ixy="0" ixz="0" iyy="100" iyz="0" izz="100" />
        </inertial>
        <visual>
            <origin xyz="-0.4175754253294097 0 0" rpy="0 0 0"/>
            <geometry>
                <box size="0.8351508506588194 0.7020562004999458 0.6050328051368262" />
            </geometry>
            <material name="Blue">
                <color rgba="0 0 1 1"/>
            </material>
        </visual>
        <collision>
            <origin xyz="-0.4175754253294097 0 0" rpy="0 0 0"/>
            <geometry>
                <box size="0.8351508506588194 0.7020562004999458 0.6050328051368262" />
            </geometry>
        </collision>
    </link>
    <joint name="Link1MinXLink0_Link1MinXLink1" type="revolute">
       <parent link="Link1MinXLink0"/>
       <child  link="Link1MinXLink1"/>
       <origin rpy="0 0 0" xyz="-0.8351508506588194 0 0" />
     <axis xyz="1 0 0"/>
       <limit effort="0.0" lower="-3.14159" upper="3.14159" velocity="0.0"/>
    </joint>
    <link name="Link1MinXLink1">
        <inertial>
            <origin xyz="-0.4175754253294097 0 0" rpy="0 0 0"/>
            <mass value="1" />
            <inertia ixx="100" ixy="0" ixz="0" iyy="100" iyz="0" izz="100" />
        </inertial>
        <visual>
            <origin xyz="-0.4175754253294097 0 0" rpy="0 0 0"/>
            <geometry>
                <box size="0.8351508506588194 0.7020562004999458 0.6050328051368262" />
            </geometry>
            <material name="Blue">
                <color rgba="0 0 1 1"/>
            </material>
        </visual>
        <collision>
            <origin xyz="-0.4175754253294097 0 0" rpy="0 0 0"/>
            <geometry>
                <box size="0.8351508506588194 0.7020562004999458 0.6050328051368262" />
            </geometry>
        </collision>
    </link>
    <joint name="Link1_Link1ZLink0" type="revolute">
       <parent link="Link1"/>
       <child  link="Link1ZLink0"/>
       <origin rpy="0 0 0" xyz="0 0.37763937999066 0.43420976229280706" />
     <axis xyz="0 0 1"/>
       <limit effort="0.0" lower="-3.14159" upper="3.14159" velocity="0.0"/>
    </joint>
    <link name="Link1ZLink0">
        <inertial>
            <origin xyz="0 0 0.30349177293483437" rpy="0 0 0"/>
            <mass value="1" />
            <inertia ixx="100" ixy="0" ixz="0" iyy="100" iyz="0" izz="100" />
        </inertial>
        <visual>
            <origin xyz="0 0 0.30349177293483437" rpy="0 0 0"/>
            <geometry>
                <box size="0.6861776181952026 0.6524216804594861 0.6069835458696687" />
            </geometry>
            <material name="Blue">
                <color rgba="0 0 1 1"/>
            </material>
        </visual>
        <collision>
            <origin xyz="0 0 0.30349177293483437" rpy="0 0 0"/>
            <geometry>
                <box size="0.6861776181952026 0.6524216804594861 0.6069835458696687" />
            </geometry>
        </collision>
    </link>
    <joint name="Link1ZLink0_Link1ZLink1" type="revolute">
       <parent link="Link1ZLink0"/>
       <child  link="Link1ZLink1"/>
       <origin rpy="0 0 0" xyz="0 0 0.6069835458696687" />
     <axis xyz="0 0 1"/>
       <limit effort="0.0" lower="-3.14159" upper="3.14159" velocity="0.0"/>
    </joint>
    <link name="Link1ZLink1">
        <inertial>
            <origin xyz="0 0 0.30349177293483437" rpy="0 0 0"/>
            <mass value="1" />
            <inertia ixx="100" ixy="0" ixz="0" iyy="100" iyz="0" izz="100" />
        </inertial>
        <visual>
            <origin xyz="0 0 0.30349177293483437" rpy="0 0 0"/>
            <geometry>
                <box size="0.6861776181952026 0.6524216804594861 0.6069835458696687" />
            </geometry>
            <material name="Green">
                <color rgba="0 1 0 1"/>
            </material>
        </visual>
        <collision>
            <origin xyz="0 0 0.30349177293483437" rpy="0 0 0"/>
            <geometry>
                <box size="0.6861776181952026 0.6524216804594861 0.6069835458696687" />
            </geometry>
        </collision>
    </link>
    <joint name="Link1_Link2" type="revolute">
       <parent link="Link1"/>
       <child  link="Link2"/>
       <origin rpy="0 0 0" xyz="0 0.75527875998132 0" />
     <axis xyz="1 0 0"/>
       <limit effort="0.0" lower="-3.14159" upper="3.14159" velocity="0.0"/>
    </joint>
    <link name="Link2">
        <inertial>
            <origin xyz="0 0.4899602087232093 0" rpy="0 0 0"/>
            <mass value="1" />
            <inertia ixx="100" ixy="0" ixz="0" iyy="100" iyz="0" izz="100" />
        </inertial>
        <visual>
            <origin xyz="0 0.4899602087232093 0" rpy="0 0 0"/>
            <geometry>
                <box size="0.6919471427240963 0.9799204174464186 0.6823051030403615" />
            </geometry>
            <material name="Green">
                <color rgba="0 1 0 1"/>
            </material>
        </visual>
        <collision>
            <origin xyz="0 0.4899602087232093 0" rpy="0 0 0"/>
            <geometry>
                <box size="0.6919471427240963 0.9799204174464186 0.6823051030403615" />
            </geometry>
        </collision>
    </link>
    <joint name="Link2_Link2XLink0" type="revolute">
       <parent link="Link2"/>
       <child  link="Link2XLink0"/>
       <origin rpy="0 0 0" xyz="0.34597357136204815 0.4899602087232093 0" />
     <axis xyz="1 0 0"/>
       <limit effort="0.0" lower="-3.14159" upper="3.14159" velocity="0.0"/>
    </joint>
    <link name="Link2XLink0">
        <inertial>
            <origin xyz="0.35735862664101514 0 0" rpy="0 0 0"/>
            <mass value="1" />
            <inertia ixx="100" ixy="0" ixz="0" iyy="100" iyz="0" izz="100" />
        </inertial>
        <visual>
            <origin xyz="0.35735862664101514 0 0" rpy="0 0 0"/>
            <geometry>
                <box size="0.7147172532820303 0.8384065580312116 0.8745134072357004" />
            </geometry>
            <material name="Blue">
                <color rgba="0 0 1 1"/>
            </material>
        </visual>
        <collision>
            <origin xyz="0.35735862664101514 0 0" rpy="0 0 0"/>
            <geometry>
                <box size="0.7147172532820303 0.8384065580312116 0.8745134072357004" />
            </geometry>
        </collision>
    </link>
    <joint name="Link2XLink0_Link2XLink1" type="revolute">
       <parent link="Link2XLink0"/>
       <child  link="Link2XLink1"/>
       <origin rpy="0 0 0" xyz="0.7147172532820303 0 0" />
     <axis xyz="1 0 0"/>
       <limit effort="0.0" lower="-3.14159" upper="3.14159" velocity="0.0"/>
    </joint>
    <link name="Link2XLink1">
        <inertial>
            <origin xyz="0.35735862664101514 0 0" rpy="0 0 0"/>
            <mass value="1" />
            <inertia ixx="100" ixy="0" ixz="0" iyy="100" iyz="0" izz="100" />
        </inertial>
        <visual>
            <origin xyz="0.35735862664101514 0 0" rpy="0 0 0"/>
            <geometry>
                <box size="0.7147172532820303 0.8384065580312116 0.8745134072357004" />
            </geometry>
            <material name="Blue">
                <color rgba="0 0 1 1"/>
            </material>
        </visual>
        <collision>
            <origin xyz="0.35735862664101514 0 0" rpy="0 0 0"/>
            <geometry>
                <box size="0.7147172532820303 0.8384065580312116 0.8745134072357004" />
            </geometry>
        </collision>
    </link>
    <joint name="Link2_Link2MinXLink0" type="revolute">
       <parent link="Link2"/>
       <child  link="Link2MinXLink0"/>
       <origin rpy="0 0 0" xyz="-0.34597357136204815 0.4899602087232093 0" />
     <axis xyz="1 0 0"/>
       <limit effort="0.0" lower="-3.14159" upper="3.14159" velocity="0.0"/>
    </joint>
    <link name="Link2MinXLink0">
        <inertial>
            <origin xyz="-0.46406496769767014 0 0" rpy="0 0 0"/>
            <mass value="1" />
            <inertia ixx="100" ixy="0" ixz="0" iyy="100" iyz="0" izz="100" />
        </inertial>
        <visual>
            <origin xyz="-0.46406496769767014 0 0" rpy="0 0 0"/>
            <geometry>
                <box size="0.9281299353953403 0.7632129097728488 0.7207264546857362" />
            </geometry>
            <material name="Green">
                <color rgba="0 1 0 1"/>
            </material>
        </visual>
        <collision>
            <origin xyz="-0.46406496769767014 0 0" rpy="0 0 0"/>
            <geometry>
                <box size="0.9281299353953403 0.7632129097728488 0.7207264546857362" />
            </geometry>
        </collision>
    </link>
    <joint name="Link2_Link2ZLink0" type="revolute">
       <parent link="Link2"/>
       <child  link="Link2ZLink0"/>
       <origin rpy="0 0 0" xyz="0 0.4899602087232093 0.34115255152018076" />
     <axis xyz="0 0 1"/>
       <limit effort="0.0" lower="-3.14159" upper="3.14159" velocity="0.0"/>
    </joint>
    <link name="Link2ZLink0">
        <inertial>
            <origin xyz="0 0 0.3666174343861795" rpy="0 0 0"/>
            <mass value="1" />
            <inertia ixx="100" ixy="0" ixz="0" iyy="100" iyz="0" izz="100" />
        </inertial>
        <visual>
            <origin xyz="0 0 0.3666174343861795" rpy="0 0 0"/>
            <geometry>
                <box size="0.6919471427240963 0.8583697115333657 0.733234868772359" />
            </geometry>
            <material name="Green">
                <color rgba="0 1 0 1"/>
            </material>
        </visual>
        <collision>
            <origin xyz="0 0 0.3666174343861795" rpy="0 0 0"/>
            <geometry>
                <box size="0.6919471427240963 0.8583697115333657 0.733234868772359" />
            </geometry>
        </collision>
    </link>
</robot>